<?xml version='1.0'?>

<robot name="rosbot_pro" 
  xmlns:xacro="http://www.ros.org/wiki/xacro">

    <xacro:arg name="robot_namespace" default=""/>

    <!-- Links - no materials or shapes for now, to be simple -->
    <link name="base_link">
    </link>

    <link name="camera_link">
    </link>

    <link name="camera_rgb_frame">
    </link>

    <link name="laser_link">
    </link>

    <!-- Joints -->
    <joint name="camera_base" type="revolute">
        <parent link="base_link"/>
        <child link="camera_link"/>
        <origin rpy="0 0 0" xyz="0 0 0" />
        <limit effort="1000" lower="-1.5" upper="1.5" velocity="0.5" />
        <axis xyz="0 1 0" />
    </joint>

    <joint name="camera_frame" type="fixed">
        <parent link="camera_link"/>
        <child link="camera_rgb_frame"/>
        <origin rpy="0 0 0" xyz="0 0 0" />
    </joint>
  
    <joint name="laser_fixed" type="fixed">
        <parent link="base_link"/>
        <child link="laser_link"/>
        <origin rpy="0 0 0" xyz="0 0 0" />
    </joint>


</robot>
